<?xml version="1.0" ?>
<!-- =================================================================================== -->
<!-- |    This document was autogenerated by xacro from ./dog.xacro                    | -->
<!-- |    EDITING THIS FILE BY HAND IS NOT RECOMMENDED                                 | -->
<!-- =================================================================================== -->
<robot name="dog">
  <!-- 躯干绕z轴转动惯量(kg·m²) -->
  <!-- 髋关节绕z轴转动惯量(kg·m²) -->
  <!-- 大腿绕z轴转动惯量(kg·m²) -->
  <!-- 小腿绕z轴转动惯量(kg·m²) -->
  <!-- 脚部绕z轴转动惯量(kg·m²) -->
  <!-- 脚部z轴方向偏移量(m) -->
  <!-- 髋x轴关节最大力矩(N·m) -->
  <!-- 髋y轴关节最大力矩(N·m) -->
  <!-- 膝关节最大力矩(N·m) -->
  <link name="TORSO">
    <inertial>
      <origin xyz="0 0 0"/>
      <mass value="5.6056"/>
      <inertia ixx="0.02456" ixy="0" ixz="0" iyy="0.05518" iyz="0" izz="0.07016"/>
    </inertial>
    <visual>
      <geometry>
        <mesh filename="package://dog_bringup/meshes/lite3/torso.STL"/>
      </geometry>
    </visual>
    <collision>
      <origin xyz="0 0 0.01"/>
      <geometry>
        <box size="0.5 0.1 0.12"/>
      </geometry>
    </collision>
    <collision>
      <origin xyz="0 0 0.01"/>
      <geometry>
        <box size="0.25 0.2 0.12"/>
      </geometry>
    </collision>
  </link>
  <link name="imu_link">
    <inertial>
      <mass value="0.1"/>
      <origin rpy="0 0 0" xyz="0 0 0"/>
      <inertia ixx="0.001" ixy="0.0" ixz="0.0" iyy="0.001" iyz="0.0" izz="0.001"/>
    </inertial>
  </link>
  <joint name="imu_joint" type="fixed">
    <parent link="TORSO"/>
    <child link="imu_link"/>
    <origin rpy="0 0 0" xyz="0 0 0"/>
  </joint>
  <gazebo reference="imu_joint">
    <preserveFixedJoint>true</preserveFixedJoint>
  </gazebo>
  <link name="base_link"/>
  <joint name="base_joint" type="fixed">
    <parent link="base_link"/>
    <child link="TORSO"/>
    <origin rpy="0 0 0" xyz="0 0 0"/>
  </joint>
  <link name="LF_HIP">
    <inertial>
      <origin xyz="-0.00601 -0.0066532 0.00034295"/>
      <mass value="0.55"/>
      <inertia ixx="0.0003949" ixy="0" ixz="0" iyy="0.0004028" iyz="0" izz="0.0004472"/>
    </inertial>
    <visual>
      <geometry>
        <mesh filename="package://dog_bringup/meshes/lite3/hip.STL" scale="1 1 1"/>
      </geometry>
    </visual>
    <collision>
      <origin rpy="1.57079632 0 0" xyz="0 0.05 0"/>
      <geometry>
        <cylinder length="0.15" radius="0.04"/>
      </geometry>
    </collision>
  </link>
  <joint name="LF_HAA" type="revolute">
    <origin xyz="0.1745 0.062 0"/>
    <parent link="TORSO"/>
    <child link="LF_HIP"/>
    <axis xyz="-1 0 0"/>
    <limit effort="24" lower="-0.523" upper="0.523" velocity="26.2"/>
    <dynamics damping="0.05" friction="0.01"/>
  </joint>
  <link name="LF_THIGH">
    <inertial>
      <origin xyz="-0.0039245 -0.014632 -0.025146"/>
      <mass value="0.86"/>
      <inertia ixx="0.005736" ixy="0" ixz="0" iyy="0.00496" iyz="0" izz="0.001436"/>
    </inertial>
    <visual>
      <geometry>
        <mesh filename="package://dog_bringup/meshes/lite3/thigh.STL" scale="1 1 1"/>
      </geometry>
    </visual>
    <collision>
      <origin xyz="-0.015 0 -0.08"/>
      <geometry>
        <box size="0.04 0.045 0.2"/>
      </geometry>
    </collision>
  </link>
  <joint name="LF_HFE" type="revolute">
    <origin xyz="0 0.09735 0"/>
    <parent link="LF_HIP"/>
    <child link="LF_THIGH"/>
    <axis xyz="0 -1 0"/>
    <limit effort="24" lower="-2.67" upper="0.314" velocity="26.2"/>
    <dynamics damping="0.05" friction="0.01"/>
  </joint>
  <link name="LF_SHANK">
    <inertial>
      <origin xyz="0.0064794 -1.45e-06 -0.12157"/>
      <mass value="0.153"/>
      <inertia ixx="0.00089039" ixy="0" ixz="0" iyy="0.00090672" iyz="0" izz="3.1266e-05"/>
    </inertial>
    <visual>
      <geometry>
        <mesh filename="package://dog_bringup/meshes/lite3/shank.STL"/>
      </geometry>
    </visual>
    <collision>
      <origin rpy="0 -0.2 0" xyz="0.005 0 -0.03"/>
      <geometry>
        <cylinder length="0.12" radius="0.015"/>
      </geometry>
    </collision>
    <collision>
      <origin rpy="0 0.15 0" xyz="0.01 0 -0.14"/>
      <geometry>
        <cylinder length="0.10" radius="0.015"/>
      </geometry>
    </collision>
  </link>
  <joint name="LF_KFE" type="revolute">
    <origin xyz="0 0 -0.2"/>
    <parent link="LF_THIGH"/>
    <child link="LF_SHANK"/>
    <axis xyz="0 -1 0"/>
    <limit effort="36" lower="0.524" upper="2.792" velocity="17.3"/>
    <dynamics damping="0.05" friction="0.01"/>
  </joint>
  <link name="LF_FOOT">
    <collision name="LF_FOOT_collision">
      <origin rpy="1.57079632679 0 0"/>
      <geometry>
        <sphere radius="0.023"/>
      </geometry>
    </collision>
    <inertial>
      <mass value="0.06"/>
      <inertia ixx="0.0001" ixy="0" ixz="0" iyy="0.0001" iyz="0" izz="0.0001"/>
    </inertial>
  </link>
  <joint dont_collapse="true" name="LF_Ankle" type="fixed">
    <parent link="LF_SHANK"/>
    <child link="LF_FOOT"/>
    <origin xyz="0 0 -0.21012"/>
  </joint>
  <gazebo reference="LF_Ankle">
    <preserveFixedJoint>true</preserveFixedJoint>
  </gazebo>
  <gazebo reference="LF_HIP">
    <mu1>0.2</mu1>
    <mu2>0.2</mu2>
    <material>Gazebo/Yellow</material>
    <self_collide>1</self_collide>
  </gazebo>
  <gazebo reference="LF_THIGH">
    <mu1>0.2</mu1>
    <mu2>0.2</mu2>
    <material>Gazebo/Blue</material>
    <self_collide>0</self_collide>
    <kp value="1000000.0"/>
    <kd value="100.0"/>
  </gazebo>
  <gazebo reference="LF_SHANK">
    <mu1>0.6</mu1>
    <mu2>0.6</mu2>
    <material>Gazebo/DarkGrey</material>
    <self_collide>1</self_collide>
  </gazebo>
  <gazebo reference="LF_FOOT">
    <mu1>0.6</mu1>
    <mu2>0.6</mu2>
    <kp>1000000.0</kp>
    <kd>100.0</kd>
    <minDepth>0.001</minDepth>
    <self_collide>1</self_collide>
    <sensor name="LF_contact_sensor" type="contact">
      <always_on>true</always_on>
      <update_rate>1000</update_rate>
      <contact>
        <collision>LF_FOOT_collision</collision>
      </contact>
    </sensor>
  </gazebo>
  <link name="LH_HIP">
    <inertial>
      <origin xyz="-0.00601 -0.0066532 0.00034295"/>
      <mass value="0.55"/>
      <inertia ixx="0.0003949" ixy="0" ixz="0" iyy="0.0004028" iyz="0" izz="0.0004472"/>
    </inertial>
    <visual>
      <geometry>
        <mesh filename="package://dog_bringup/meshes/lite3/hip.STL" scale="-1 1 1"/>
      </geometry>
    </visual>
    <collision>
      <origin rpy="1.57079632 0 0" xyz="0 0.05 0"/>
      <geometry>
        <cylinder length="0.15" radius="0.04"/>
      </geometry>
    </collision>
  </link>
  <joint name="LH_HAA" type="revolute">
    <origin xyz="-0.1745 0.062 0"/>
    <parent link="TORSO"/>
    <child link="LH_HIP"/>
    <axis xyz="-1 0 0"/>
    <limit effort="24" lower="-0.523" upper="0.523" velocity="26.2"/>
    <dynamics damping="0.05" friction="0.01"/>
  </joint>
  <link name="LH_THIGH">
    <inertial>
      <origin xyz="-0.0039245 -0.014632 -0.025146"/>
      <mass value="0.86"/>
      <inertia ixx="0.005736" ixy="0" ixz="0" iyy="0.00496" iyz="0" izz="0.001436"/>
    </inertial>
    <visual>
      <geometry>
        <mesh filename="package://dog_bringup/meshes/lite3/thigh.STL" scale="1 1 1"/>
      </geometry>
    </visual>
    <collision>
      <origin xyz="-0.015 0 -0.08"/>
      <geometry>
        <box size="0.04 0.045 0.2"/>
      </geometry>
    </collision>
  </link>
  <joint name="LH_HFE" type="revolute">
    <origin xyz="0 0.09735 0"/>
    <parent link="LH_HIP"/>
    <child link="LH_THIGH"/>
    <axis xyz="0 -1 0"/>
    <limit effort="24" lower="-2.67" upper="0.314" velocity="26.2"/>
    <dynamics damping="0.05" friction="0.01"/>
  </joint>
  <link name="LH_SHANK">
    <inertial>
      <origin xyz="0.0064794 -1.45e-06 -0.12157"/>
      <mass value="0.153"/>
      <inertia ixx="0.00089039" ixy="0" ixz="0" iyy="0.00090672" iyz="0" izz="3.1266e-05"/>
    </inertial>
    <visual>
      <geometry>
        <mesh filename="package://dog_bringup/meshes/lite3/shank.STL"/>
      </geometry>
    </visual>
    <collision>
      <origin rpy="0 -0.2 0" xyz="0.005 0 -0.03"/>
      <geometry>
        <cylinder length="0.12" radius="0.015"/>
      </geometry>
    </collision>
    <collision>
      <origin rpy="0 0.15 0" xyz="0.01 0 -0.14"/>
      <geometry>
        <cylinder length="0.10" radius="0.015"/>
      </geometry>
    </collision>
  </link>
  <joint name="LH_KFE" type="revolute">
    <origin xyz="0 0 -0.2"/>
    <parent link="LH_THIGH"/>
    <child link="LH_SHANK"/>
    <axis xyz="0 -1 0"/>
    <limit effort="36" lower="0.524" upper="2.792" velocity="17.3"/>
    <dynamics damping="0.05" friction="0.01"/>
  </joint>
  <link name="LH_FOOT">
    <collision name="LH_FOOT_collision">
      <origin rpy="1.57079632679 0 0"/>
      <geometry>
        <sphere radius="0.023"/>
      </geometry>
    </collision>
    <inertial>
      <mass value="0.06"/>
      <inertia ixx="0.0001" ixy="0" ixz="0" iyy="0.0001" iyz="0" izz="0.0001"/>
    </inertial>
  </link>
  <joint dont_collapse="true" name="LH_Ankle" type="fixed">
    <parent link="LH_SHANK"/>
    <child link="LH_FOOT"/>
    <origin xyz="0 0 -0.21012"/>
  </joint>
  <gazebo reference="LH_Ankle">
    <preserveFixedJoint>true</preserveFixedJoint>
  </gazebo>
  <gazebo reference="LH_HIP">
    <mu1>0.2</mu1>
    <mu2>0.2</mu2>
    <material>Gazebo/Yellow</material>
    <self_collide>1</self_collide>
  </gazebo>
  <gazebo reference="LH_THIGH">
    <mu1>0.2</mu1>
    <mu2>0.2</mu2>
    <material>Gazebo/Blue</material>
    <self_collide>0</self_collide>
    <kp value="1000000.0"/>
    <kd value="100.0"/>
  </gazebo>
  <gazebo reference="LH_SHANK">
    <mu1>0.6</mu1>
    <mu2>0.6</mu2>
    <material>Gazebo/DarkGrey</material>
    <self_collide>1</self_collide>
  </gazebo>
  <gazebo reference="LH_FOOT">
    <mu1>0.6</mu1>
    <mu2>0.6</mu2>
    <kp>1000000.0</kp>
    <kd>100.0</kd>
    <minDepth>0.001</minDepth>
    <self_collide>1</self_collide>
    <sensor name="LH_contact_sensor" type="contact">
      <always_on>true</always_on>
      <update_rate>1000</update_rate>
      <contact>
        <collision>LH_FOOT_collision</collision>
      </contact>
    </sensor>
  </gazebo>
  <link name="RF_HIP">
    <inertial>
      <origin xyz="-0.00601 0.0066532 0.00034295"/>
      <mass value="0.55"/>
      <inertia ixx="0.0003949" ixy="0" ixz="0" iyy="0.0004028" iyz="0" izz="0.0004472"/>
    </inertial>
    <visual>
      <geometry>
        <mesh filename="package://dog_bringup/meshes/lite3/hip.STL" scale="1 -1 1"/>
      </geometry>
    </visual>
    <collision>
      <origin rpy="1.57079632 0 0" xyz="0 -0.05 0"/>
      <geometry>
        <cylinder length="0.15" radius="0.04"/>
      </geometry>
    </collision>
  </link>
  <joint name="RF_HAA" type="revolute">
    <origin xyz="0.1745 -0.062 0"/>
    <parent link="TORSO"/>
    <child link="RF_HIP"/>
    <axis xyz="-1 0 0"/>
    <limit effort="24" lower="-0.523" upper="0.523" velocity="26.2"/>
    <dynamics damping="0.05" friction="0.01"/>
  </joint>
  <link name="RF_THIGH">
    <inertial>
      <origin xyz="-0.0039245 0.014632 -0.025146"/>
      <mass value="0.86"/>
      <inertia ixx="0.005736" ixy="0" ixz="0" iyy="0.00496" iyz="0" izz="0.001436"/>
    </inertial>
    <visual>
      <geometry>
        <mesh filename="package://dog_bringup/meshes/lite3/thigh.STL" scale="1 -1 1"/>
      </geometry>
    </visual>
    <collision>
      <origin xyz="-0.015 0 -0.08"/>
      <geometry>
        <box size="0.04 0.045 0.2"/>
      </geometry>
    </collision>
  </link>
  <joint name="RF_HFE" type="revolute">
    <origin xyz="0 -0.09735 0"/>
    <parent link="RF_HIP"/>
    <child link="RF_THIGH"/>
    <axis xyz="0 -1 0"/>
    <limit effort="24" lower="-2.67" upper="0.314" velocity="26.2"/>
    <dynamics damping="0.05" friction="0.01"/>
  </joint>
  <link name="RF_SHANK">
    <inertial>
      <origin xyz="0.0064794 -1.45e-06 -0.12157"/>
      <mass value="0.153"/>
      <inertia ixx="0.00089039" ixy="0" ixz="0" iyy="0.00090672" iyz="0" izz="3.1266e-05"/>
    </inertial>
    <visual>
      <geometry>
        <mesh filename="package://dog_bringup/meshes/lite3/shank.STL"/>
      </geometry>
    </visual>
    <collision>
      <origin rpy="0 -0.2 0" xyz="0.005 0 -0.03"/>
      <geometry>
        <cylinder length="0.12" radius="0.015"/>
      </geometry>
    </collision>
    <collision>
      <origin rpy="0 0.15 0" xyz="0.01 0 -0.14"/>
      <geometry>
        <cylinder length="0.10" radius="0.015"/>
      </geometry>
    </collision>
  </link>
  <joint name="RF_KFE" type="revolute">
    <origin xyz="0 0 -0.2"/>
    <parent link="RF_THIGH"/>
    <child link="RF_SHANK"/>
    <axis xyz="0 -1 0"/>
    <limit effort="36" lower="0.524" upper="2.792" velocity="17.3"/>
    <dynamics damping="0.05" friction="0.01"/>
  </joint>
  <link name="RF_FOOT">
    <collision name="RF_FOOT_collision">
      <origin rpy="1.57079632679 0 0"/>
      <geometry>
        <sphere radius="0.023"/>
      </geometry>
    </collision>
    <inertial>
      <mass value="0.06"/>
      <inertia ixx="0.0001" ixy="0" ixz="0" iyy="0.0001" iyz="0" izz="0.0001"/>
    </inertial>
  </link>
  <joint dont_collapse="true" name="RF_Ankle" type="fixed">
    <parent link="RF_SHANK"/>
    <child link="RF_FOOT"/>
    <origin xyz="0 0 -0.21012"/>
  </joint>
  <gazebo reference="RF_Ankle">
    <preserveFixedJoint>true</preserveFixedJoint>
  </gazebo>
  <gazebo reference="RF_HIP">
    <mu1>0.2</mu1>
    <mu2>0.2</mu2>
    <material>Gazebo/Yellow</material>
    <self_collide>1</self_collide>
  </gazebo>
  <gazebo reference="RF_THIGH">
    <mu1>0.2</mu1>
    <mu2>0.2</mu2>
    <material>Gazebo/Blue</material>
    <self_collide>0</self_collide>
    <kp value="1000000.0"/>
    <kd value="100.0"/>
  </gazebo>
  <gazebo reference="RF_SHANK">
    <mu1>0.6</mu1>
    <mu2>0.6</mu2>
    <material>Gazebo/DarkGrey</material>
    <self_collide>1</self_collide>
  </gazebo>
  <gazebo reference="RF_FOOT">
    <mu1>0.6</mu1>
    <mu2>0.6</mu2>
    <kp>1000000.0</kp>
    <kd>100.0</kd>
    <minDepth>0.001</minDepth>
    <self_collide>1</self_collide>
    <sensor name="RF_contact_sensor" type="contact">
      <always_on>true</always_on>
      <update_rate>1000</update_rate>
      <contact>
        <collision>RF_FOOT_collision</collision>
      </contact>
    </sensor>
  </gazebo>
  <link name="RH_HIP">
    <inertial>
      <origin xyz="-0.00601 0.0066532 0.00034295"/>
      <mass value="0.55"/>
      <inertia ixx="0.0003949" ixy="0" ixz="0" iyy="0.0004028" iyz="0" izz="0.0004472"/>
    </inertial>
    <visual>
      <geometry>
        <mesh filename="package://dog_bringup/meshes/lite3/hip.STL" scale="-1 -1 1"/>
      </geometry>
    </visual>
    <collision>
      <origin rpy="1.57079632 0 0" xyz="0 -0.05 0"/>
      <geometry>
        <cylinder length="0.15" radius="0.04"/>
      </geometry>
    </collision>
  </link>
  <joint name="RH_HAA" type="revolute">
    <origin xyz="-0.1745 -0.062 0"/>
    <parent link="TORSO"/>
    <child link="RH_HIP"/>
    <axis xyz="-1 0 0"/>
    <limit effort="24" lower="-0.523" upper="0.523" velocity="26.2"/>
    <dynamics damping="0.05" friction="0.01"/>
  </joint>
  <link name="RH_THIGH">
    <inertial>
      <origin xyz="-0.0039245 0.014632 -0.025146"/>
      <mass value="0.86"/>
      <inertia ixx="0.005736" ixy="0" ixz="0" iyy="0.00496" iyz="0" izz="0.001436"/>
    </inertial>
    <visual>
      <geometry>
        <mesh filename="package://dog_bringup/meshes/lite3/thigh.STL" scale="1 -1 1"/>
      </geometry>
    </visual>
    <collision>
      <origin xyz="-0.015 0 -0.08"/>
      <geometry>
        <box size="0.04 0.045 0.2"/>
      </geometry>
    </collision>
  </link>
  <joint name="RH_HFE" type="revolute">
    <origin xyz="0 -0.09735 0"/>
    <parent link="RH_HIP"/>
    <child link="RH_THIGH"/>
    <axis xyz="0 -1 0"/>
    <limit effort="24" lower="-2.67" upper="0.314" velocity="26.2"/>
    <dynamics damping="0.05" friction="0.01"/>
  </joint>
  <link name="RH_SHANK">
    <inertial>
      <origin xyz="0.0064794 -1.45e-06 -0.12157"/>
      <mass value="0.153"/>
      <inertia ixx="0.00089039" ixy="0" ixz="0" iyy="0.00090672" iyz="0" izz="3.1266e-05"/>
    </inertial>
    <visual>
      <geometry>
        <mesh filename="package://dog_bringup/meshes/lite3/shank.STL"/>
      </geometry>
    </visual>
    <collision>
      <origin rpy="0 -0.2 0" xyz="0.005 0 -0.03"/>
      <geometry>
        <cylinder length="0.12" radius="0.015"/>
      </geometry>
    </collision>
    <collision>
      <origin rpy="0 0.15 0" xyz="0.01 0 -0.14"/>
      <geometry>
        <cylinder length="0.10" radius="0.015"/>
      </geometry>
    </collision>
  </link>
  <joint name="RH_KFE" type="revolute">
    <origin xyz="0 0 -0.2"/>
    <parent link="RH_THIGH"/>
    <child link="RH_SHANK"/>
    <axis xyz="0 -1 0"/>
    <limit effort="36" lower="0.524" upper="2.792" velocity="17.3"/>
    <dynamics damping="0.05" friction="0.01"/>
  </joint>
  <link name="RH_FOOT">
    <collision name="RH_FOOT_collision">
      <origin rpy="1.57079632679 0 0"/>
      <geometry>
        <sphere radius="0.023"/>
      </geometry>
    </collision>
    <inertial>
      <mass value="0.06"/>
      <inertia ixx="0.0001" ixy="0" ixz="0" iyy="0.0001" iyz="0" izz="0.0001"/>
    </inertial>
  </link>
  <joint dont_collapse="true" name="RH_Ankle" type="fixed">
    <parent link="RH_SHANK"/>
    <child link="RH_FOOT"/>
    <origin xyz="0 0 -0.21012"/>
  </joint>
  <gazebo reference="RH_Ankle">
    <preserveFixedJoint>true</preserveFixedJoint>
  </gazebo>
  <gazebo reference="RH_HIP">
    <mu1>0.2</mu1>
    <mu2>0.2</mu2>
    <material>Gazebo/Yellow</material>
    <self_collide>1</self_collide>
  </gazebo>
  <gazebo reference="RH_THIGH">
    <mu1>0.2</mu1>
    <mu2>0.2</mu2>
    <material>Gazebo/Blue</material>
    <self_collide>0</self_collide>
    <kp value="1000000.0"/>
    <kd value="100.0"/>
  </gazebo>
  <gazebo reference="RH_SHANK">
    <mu1>0.6</mu1>
    <mu2>0.6</mu2>
    <material>Gazebo/DarkGrey</material>
    <self_collide>1</self_collide>
  </gazebo>
  <gazebo reference="RH_FOOT">
    <mu1>0.6</mu1>
    <mu2>0.6</mu2>
    <kp>1000000.0</kp>
    <kd>100.0</kd>
    <minDepth>0.001</minDepth>
    <self_collide>1</self_collide>
    <sensor name="RH_contact_sensor" type="contact">
      <always_on>true</always_on>
      <update_rate>1000</update_rate>
      <contact>
        <collision>RH_FOOT_collision</collision>
      </contact>
    </sensor>
  </gazebo>
  <ros2_control name="dog_System" type="system">
    <hardware>
      <!-- <plugin>gazebo_ros2_control/GazeboSystem</plugin> -->
      <plugin>dog_hardware/DogGazeboHW</plugin>
      <param name="delay">0.009</param>
      <param name="imu_accel_var">0.0</param>
      <param name="imu_gyro_var">0.0004</param>
      <param name="imu_ori_var">0.0012</param>
    </hardware>
    <sensor name="imu_sensor">
      <state_interface name="orientation.x"/>
      <state_interface name="orientation.y"/>
      <state_interface name="orientation.z"/>
      <state_interface name="orientation.w"/>
      <state_interface name="angular_velocity.x"/>
      <state_interface name="angular_velocity.y"/>
      <state_interface name="angular_velocity.z"/>
      <state_interface name="linear_acceleration.x"/>
      <state_interface name="linear_acceleration.y"/>
      <state_interface name="linear_acceleration.z"/>
      <state_interface name="orientation_covariance"/>
      <state_interface name="angular_velocity_covariance"/>
      <state_interface name="linear_acceleration_covariance"/>
    </sensor>
    <sensor name="LF_contact_sensor">
      <state_interface name="contact"/>
    </sensor>
    <sensor name="RF_contact_sensor">
      <state_interface name="contact"/>
    </sensor>
    <sensor name="LH_contact_sensor">
      <state_interface name="contact"/>
    </sensor>
    <sensor name="RH_contact_sensor">
      <state_interface name="contact"/>
    </sensor>
    <joint name="LF_HAA">
      <command_interface name="effort">
        <param name="min">-24</param>
        <param name="max">24</param>
      </command_interface>
      <command_interface name="position"/>
      <command_interface name="velocity"/>
      <command_interface name="kp"/>
      <command_interface name="kd"/>
      <command_interface name="mode"/>
      <state_interface name="driver_tem"/>
      <state_interface name="motor_tem"/>
      <state_interface name="error_code"/>
      <state_interface name="position"/>
      <state_interface name="velocity"/>
      <state_interface name="effort"/>
    </joint>
    <joint name="LF_HFE">
      <command_interface name="effort">
        <param name="min">-24</param>
        <param name="max">24</param>
      </command_interface>
      <command_interface name="position"/>
      <command_interface name="velocity"/>
      <command_interface name="kp"/>
      <command_interface name="kd"/>
      <command_interface name="mode"/>
      <state_interface name="driver_tem"/>
      <state_interface name="motor_tem"/>
      <state_interface name="error_code"/>
      <state_interface name="position"/>
      <state_interface name="velocity"/>
      <state_interface name="effort"/>
    </joint>
    <joint name="LF_KFE">
      <command_interface name="effort">
        <param name="min">-36</param>
        <param name="max">36</param>
      </command_interface>
      <command_interface name="position"/>
      <command_interface name="velocity"/>
      <command_interface name="kp"/>
      <command_interface name="kd"/>
      <command_interface name="mode"/>
      <state_interface name="driver_tem"/>
      <state_interface name="motor_tem"/>
      <state_interface name="error_code"/>
      <state_interface name="position"/>
      <state_interface name="velocity"/>
      <state_interface name="effort"/>
    </joint>
    <joint name="RF_HAA">
      <command_interface name="effort">
        <param name="min">-24</param>
        <param name="max">24</param>
      </command_interface>
      <command_interface name="position"/>
      <command_interface name="velocity"/>
      <command_interface name="kp"/>
      <command_interface name="kd"/>
      <command_interface name="mode"/>
      <state_interface name="driver_tem"/>
      <state_interface name="motor_tem"/>
      <state_interface name="error_code"/>
      <state_interface name="position"/>
      <state_interface name="velocity"/>
      <state_interface name="effort"/>
    </joint>
    <joint name="RF_HFE">
      <command_interface name="effort">
        <param name="min">-24</param>
        <param name="max">24</param>
      </command_interface>
      <command_interface name="position"/>
      <command_interface name="velocity"/>
      <command_interface name="kp"/>
      <command_interface name="kd"/>
      <command_interface name="mode"/>
      <state_interface name="driver_tem"/>
      <state_interface name="motor_tem"/>
      <state_interface name="error_code"/>
      <state_interface name="position"/>
      <state_interface name="velocity"/>
      <state_interface name="effort"/>
    </joint>
    <joint name="RF_KFE">
      <command_interface name="effort">
        <param name="min">-36</param>
        <param name="max">36</param>
      </command_interface>
      <command_interface name="position"/>
      <command_interface name="velocity"/>
      <command_interface name="kp"/>
      <command_interface name="kd"/>
      <command_interface name="mode"/>
      <state_interface name="driver_tem"/>
      <state_interface name="motor_tem"/>
      <state_interface name="error_code"/>
      <state_interface name="position"/>
      <state_interface name="velocity"/>
      <state_interface name="effort"/>
    </joint>
    <joint name="LH_HAA">
      <command_interface name="effort">
        <param name="min">-24</param>
        <param name="max">24</param>
      </command_interface>
      <command_interface name="position"/>
      <command_interface name="velocity"/>
      <command_interface name="kp"/>
      <command_interface name="kd"/>
      <command_interface name="mode"/>
      <state_interface name="driver_tem"/>
      <state_interface name="motor_tem"/>
      <state_interface name="error_code"/>
      <state_interface name="position"/>
      <state_interface name="velocity"/>
      <state_interface name="effort"/>
    </joint>
    <joint name="LH_HFE">
      <command_interface name="effort">
        <param name="min">-24</param>
        <param name="max">24</param>
      </command_interface>
      <command_interface name="position"/>
      <command_interface name="velocity"/>
      <command_interface name="kp"/>
      <command_interface name="kd"/>
      <command_interface name="mode"/>
      <state_interface name="driver_tem"/>
      <state_interface name="motor_tem"/>
      <state_interface name="error_code"/>
      <state_interface name="position"/>
      <state_interface name="velocity"/>
      <state_interface name="effort"/>
    </joint>
    <joint name="LH_KFE">
      <command_interface name="effort">
        <param name="min">-36</param>
        <param name="max">36</param>
      </command_interface>
      <command_interface name="position"/>
      <command_interface name="velocity"/>
      <command_interface name="kp"/>
      <command_interface name="kd"/>
      <command_interface name="mode"/>
      <state_interface name="driver_tem"/>
      <state_interface name="motor_tem"/>
      <state_interface name="error_code"/>
      <state_interface name="position"/>
      <state_interface name="velocity"/>
      <state_interface name="effort"/>
    </joint>
    <joint name="RH_HAA">
      <command_interface name="effort">
        <param name="min">-24</param>
        <param name="max">24</param>
      </command_interface>
      <command_interface name="position"/>
      <command_interface name="velocity"/>
      <command_interface name="kp"/>
      <command_interface name="kd"/>
      <command_interface name="mode"/>
      <state_interface name="driver_tem"/>
      <state_interface name="motor_tem"/>
      <state_interface name="error_code"/>
      <state_interface name="position"/>
      <state_interface name="velocity"/>
      <state_interface name="effort"/>
    </joint>
    <joint name="RH_HFE">
      <command_interface name="effort">
        <param name="min">-24</param>
        <param name="max">24</param>
      </command_interface>
      <command_interface name="position"/>
      <command_interface name="velocity"/>
      <command_interface name="kp"/>
      <command_interface name="kd"/>
      <command_interface name="mode"/>
      <state_interface name="driver_tem"/>
      <state_interface name="motor_tem"/>
      <state_interface name="error_code"/>
      <state_interface name="position"/>
      <state_interface name="velocity"/>
      <state_interface name="effort"/>
    </joint>
    <joint name="RH_KFE">
      <command_interface name="effort">
        <param name="min">-36</param>
        <param name="max">36</param>
      </command_interface>
      <command_interface name="position"/>
      <command_interface name="velocity"/>
      <command_interface name="kp"/>
      <command_interface name="kd"/>
      <command_interface name="mode"/>
      <state_interface name="driver_tem"/>
      <state_interface name="motor_tem"/>
      <state_interface name="error_code"/>
      <state_interface name="position"/>
      <state_interface name="velocity"/>
      <state_interface name="effort"/>
    </joint>
  </ros2_control>
  <gazebo reference="imu_link">
    <sensor name="imu_sensor" type="imu">
      <always_on>true</always_on>
      <update_rate>1000</update_rate>
      <imu>
        <orientation>
          <x>
            <noise type="gaussian">
              <stddev>0.034641016151377546</stddev>
            </noise>
          </x>
          <y>
            <noise type="gaussian">
              <stddev>0.034641016151377546</stddev>
            </noise>
          </y>
          <z>
            <noise type="gaussian">
              <stddev>0.034641016151377546</stddev>
            </noise>
          </z>
        </orientation>
        <linear_acceleration>
          <x>
            <noise type="gaussian">
              <stddev>0.0</stddev>
              <bias_mean>0.0</bias_mean>
            </noise>
          </x>
          <y>
            <noise type="gaussian">
              <stddev>0.0</stddev>
              <bias_mean>0.0</bias_mean>
            </noise>
          </y>
          <z>
            <noise type="gaussian">
              <stddev>0.0</stddev>
              <bias_mean>0.0</bias_mean>
            </noise>
          </z>
        </linear_acceleration>
        <angular_velocity>
          <x>
            <noise type="gaussian">
              <stddev>0.02</stddev>
              <bias_mean>0.0</bias_mean>
            </noise>
          </x>
          <y>
            <noise type="gaussian">
              <stddev>0.02</stddev>
              <bias_mean>0.0</bias_mean>
            </noise>
          </y>
          <z>
            <noise type="gaussian">
              <stddev>0.02</stddev>
              <bias_mean>0.0</bias_mean>
            </noise>
          </z>
        </angular_velocity>
      </imu>
    </sensor>
  </gazebo>
  <gazebo>
    <plugin filename="libgazebo_ros2_control.so" name="gazebo_ros2_control">
      <parameters>/home/cys/Project_Date/ROS2_workspace/dog_ws/install/dog_bringup/share/dog_bringup/config/robot_controllers.yaml</parameters>
      <robot_param>robot_description</robot_param>
      <robot_param_node>robot_state_publisher</robot_param_node>
    </plugin>
  </gazebo>
  <gazebo>
    <plugin filename="libgazebo_ros_p3d.so" name="dog_ground_truth">
      <ros>
        <remapping>odom:=/ground_truth</remapping>
      </ros>
      <body_name>base_link</body_name>
      <frame_name>world</frame_name>
      <update_rate>10.0</update_rate>
      <xyz_offset>0 0 0</xyz_offset>
      <rpy_offset>0 0 0</rpy_offset>
      <gaussian_noise>0.001</gaussian_noise>
    </plugin>
  </gazebo>
</robot>
